<?xml version="1.0" encoding="utf-8"?>
<!-- This URDF was automatically created by SolidWorks to URDF Exporter! Originally created by Stephen Brawner (brawner@gmail.com) 
     Commit Version: 1.6.0-4-g7f85cfe  Build Version: 1.6.7995.38578
     For more information, please see http://wiki.ros.org/sw_urdf_exporter -->
<robot
  name="mycobot_pro450">
  <!-- 新增一个 root -->
  <!-- <link name="world"/>

  <joint name="world_to_base" type="fixed">
    <parent link="world"/>
    <child link="base"/>
  </joint> -->
  <link
    name="base">
    <inertial>
      <origin
        xyz="-0.01511 4.6971E-05 0.064112"
        rpy="0 0 0" />
      <mass
        value="2.0381" />
      <inertia
        ixx="0.003172"
        ixy="1.9234E-06"
        ixz="0.00023241"
        iyy="0.0028769"
        iyz="-6.4243E-07"
        izz="0.0033166" />
    </inertial>
    <visual>
      <origin
        xyz="0 0 0"
        rpy="0 0 0" />
      <geometry>
        <mesh
          filename="package://mycobot_description/meshes/base.STL" />
      </geometry>
      <material
        name="">
        <color
          rgba="0.75294 0.75294 0.75294 1" />
      </material>
    </visual>
    <collision>
      <origin
        xyz="0 0 0"
        rpy="0 0 0" />
      <geometry>
        <mesh
          filename="package://mycobot_description/meshes/base.STL" />
      </geometry>
    </collision>
  </link>
  <link
    name="Link1">
    <inertial>
      <origin
        xyz="0.00045184 -0.021339 0.033413"
        rpy="0 0 0" />
      <mass
        value="0.5442" />
      <inertia
        ixx="0.00033333"
        ixy="-2.1245E-07"
        ixz="7.4454E-07"
        iyy="0.00034669"
        iyz="1.4758E-05"
        izz="0.00032553" />
    </inertial>
    <visual>
      <origin
        xyz="0 0 0"
        rpy="0 0 0" />
      <geometry>
        <mesh
          filename="package://mycobot_description/meshes/Link1.STL" />
      </geometry>
      <material
        name="">
        <color
          rgba="0.75294 0.75294 0.75294 1" />
      </material>
    </visual>
    <collision>
      <origin
        xyz="0 0 0"
        rpy="0 0 0" />
      <geometry>
        <mesh
          filename="package://mycobot_description/meshes/Link1.STL" />
      </geometry>
    </collision>
  </link>
  <joint
    name="joint1"
    type="revolute">
    <origin
      xyz="-0.00093304 0 0.17372"
      rpy="0 0 0" />
    <parent
      link="base" />
    <child
      link="Link1" />
    <axis
      xyz="0 0 1" />
    <limit
      lower="-2.8274"
      upper="2.8274"
      effort="100000"
      velocity="3.7909" />
  </joint>
  <link
    name="Link2">
    <inertial>
      <origin
        xyz="-7.4849E-05 -0.0044366 0.11981"
        rpy="0 0 0" />
      <mass
        value="0.58911" />
      <inertia
        ixx="0.002115"
        ixy="1.9472E-08"
        ixz="6.1991E-07"
        iyy="0.0021879"
        iyz="-6.4296E-05"
        izz="0.00028878" />
    </inertial>
    <visual>
      <origin
        xyz="0 0 0"
        rpy="0 0 0" />
      <geometry>
        <mesh
          filename="package://mycobot_description/meshes/Link2.STL" />
      </geometry>
      <material
        name="">
        <color
          rgba="0.75294 0.75294 0.75294 1" />
      </material>
    </visual>
    <collision>
      <origin
        xyz="0 0 0"
        rpy="0 0 0" />
      <geometry>
        <mesh
          filename="package://mycobot_description/meshes/Link2.STL" />
      </geometry>
    </collision>
  </link>
  <joint
    name="joint2"
    type="revolute">
    <origin
      xyz="0.00017155 -0.072764 0.037522"
      rpy="0 0 0.00011694" />
    <parent
      link="Link1" />
    <child
      link="Link2" />
    <axis
      xyz="0 -1 0" />
    <limit
      lower="-2.1817"
      upper="2.1817"
      effort="100000"
      velocity="3.7909" />
  </joint>
  <link
    name="Link3">
    <inertial>
      <origin
        xyz="-8.6311E-05 0.01886 0.1256"
        rpy="0 0 0" />
      <mass
        value="0.68875" />
      <inertia
        ixx="0.0017378"
        ixy="1.4956E-07"
        ixz="1.5941E-07"
        iyy="0.0017847"
        iyz="-2.8449E-05"
        izz="0.00025808" />
    </inertial>
    <visual>
      <origin
        xyz="0 0 0"
        rpy="0 0 0" />
      <geometry>
        <mesh
          filename="package://mycobot_description/meshes/Link3.STL" />
      </geometry>
      <material
        name="">
        <color
          rgba="0.75294 0.75294 0.75294 1" />
      </material>
    </visual>
    <collision>
      <origin
        xyz="0 0 0"
        rpy="0 0 0" />
      <geometry>
        <mesh
          filename="package://mycobot_description/meshes/Link3.STL" />
      </geometry>
    </collision>
  </link>
  <joint
    name="joint3"
    type="revolute">
    <origin
      xyz="-0.00011952 0.0394 0.18008"
      rpy="0 0 0" />
    <parent
      link="Link2" />
    <child
      link="Link3" />
    <axis
      xyz="0 -1 0" />
    <limit
      lower="-2.687807"
      upper="2.687807"
      effort="100000"
      velocity="3.11" />
  </joint>
  <link
    name="Link4">
    <inertial>
      <origin
        xyz="5.5307E-06 -0.019977 0.024336"
        rpy="0 0 0" />
      <mass
        value="0.55433" />
      <inertia
        ixx="0.00024787"
        ixy="-5.8392E-07"
        ixz="3.4795E-07"
        iyy="0.00024423"
        iyz="1.5884E-05"
        izz="0.000191" />
    </inertial>
    <visual>
      <origin
        xyz="0 0 0"
        rpy="0 0 0" />
      <geometry>
        <mesh
          filename="package://mycobot_description/meshes/Link4.STL" />
      </geometry>
      <material
        name="">
        <color
          rgba="0.75294 0.75294 0.75294 1" />
      </material>
    </visual>
    <collision>
      <origin
        xyz="0 0 0"
        rpy="0 0 0" />
      <geometry>
        <mesh
          filename="package://mycobot_description/meshes/Link4.STL" />
      </geometry>
    </collision>
  </link>
  <joint
    name="joint4"
    type="revolute">
    <origin
      xyz="0 -0.027001 0.173"
      rpy="0 0 0" />
    <parent
      link="Link3" />
    <child
      link="Link4" />
    <axis
      xyz="0 -1 0" />
    <limit
      lower="-2.8274"
      upper="2.8274"
      effort="100000"
      velocity="3.11" />
  </joint>
  <link
    name="Link5">
    <inertial>
      <origin
        xyz="-0.0078291 0.00061969 0.024427"
        rpy="0 0 0" />
      <mass
        value="0.53025" />
      <inertia
        ixx="0.00018687"
        ixy="-2.0057E-07"
        ixz="2.3963E-06"
        iyy="0.0002227"
        iyz="1.1581E-07"
        izz="0.00022188" />
    </inertial>
    <visual>
      <origin
        xyz="0 0 0"
        rpy="0 0 0" />
      <geometry>
        <mesh
          filename="package://mycobot_description/meshes/Link5.STL" />
      </geometry>
      <material
        name="">
        <color
          rgba="0.75294 0.75294 0.75294 1" />
      </material>
    </visual>
    <collision>
      <origin
        xyz="0 0 0"
        rpy="0 0 0" />
      <geometry>
        <mesh
          filename="package://mycobot_description/meshes/Link5.STL" />
      </geometry>
    </collision>
  </link>
  <joint
    name="joint5"
    type="revolute">
    <origin
      xyz="-1.3818E-05 -0.025698 0.070501"
      rpy="0 0 -0.00011694" />
    <parent
      link="Link4" />
    <child
      link="Link5" />
    <axis
      xyz="0 0 1" />
    <limit
      lower="-2.8274"
      upper="2.8274"
      effort="100000"
      velocity="3.11" />
  </joint>
  <link
    name="Link6">
    <inertial>
      <origin
        xyz="0.018374 0.00055432 0.00087911"
        rpy="0 0 0" />
      <mass
        value="0.10905" />
      <inertia
        ixx="4.4575E-05"
        ixy="-4.9658E-09"
        ixz="1.0564E-07"
        iyy="2.7189E-05"
        iyz="3.4068E-09"
        izz="2.7819E-05" />
    </inertial>
    <visual>
      <origin
        xyz="0 0 0"
        rpy="0 0 0" />
      <geometry>
        <mesh
          filename="package://mycobot_description/meshes/Link6.STL" />
      </geometry>
      <material
        name="">
        <color
          rgba="0.75294 0.75294 0.75294 1" />
      </material>
    </visual>
    <collision>
      <origin
        xyz="0 0 0"
        rpy="0 0 0" />
      <geometry>
        <mesh
          filename="package://mycobot_description/meshes/Link6.STL" />
      </geometry>
    </collision>
  </link>
  <joint
    name="joint6"
    type="revolute">
    <origin
      xyz="0.031841 0.0001386 0.026584"
      rpy="0 0 0.00011694" />
    <parent
      link="Link5" />
    <child
      link="Link6" />
    <axis
      xyz="1 0 0" />
    <limit
      lower="-2.879793"
      upper="2.879793"
      effort="100000"
      velocity="3.11" />
  </joint>
</robot>
